Workbook

Sheet Experiment Overview
A1: =IF('LC Raw Results'!A2>1, RIGHT('LC Raw Results'!A2, LEN('LC Raw Results'!A2)-12), IF('QS Raw Results'!A25>1, INDEX(_xlfn.TEXTSPLIT('QS Raw Results'!A25,"\"),1,7), "Paste Results File into Cell A2 of LC Raw Results or QS Raw Results")) -> 2025-11-05_095412_DEN078_RNaseP-16S.eds
B3: Experiment Aims | J3: Reagents Used
A5: 1 | B5: DEN078 Rnase P-16s qPCR | J5: Component | M5: Supplier | N5: Cat. No. | O5: Lot No.
A6: 2 | J6: TaqMan® Fast Advanced Master Mix (5x5mL) | M6: Fisher Scientific | N6: 13438456 | O6: 4444554
A7: 3 | J7: RNase P Primer-Probe (FAM) | M7: Thermofisher | N7: 4316831 | O7: 3245729
A8: 4 | J8: Human Genomic DNA | M8: Promega | N8: G3041 | O8: 0000636473
A9: 5 | J9: Human DNA Male | M9: Thermofisher | N9: 360486 | O9: 3106717
A10: 6 | J10: TaqMan® Gene Expression Assay (750rxns)* | M10: Fisher Scientific | N10: 11957021 | O10: P250904-011-F09
A11: 7 | J11: Microbial Community DNA Standard (2000ng) | M11: ZymoBIOMICS | N11: D6306 | O11: 24027229
J12: Nuclease free water or suitable alternative | M12: QIAGEN | N12: 1039498 | O12: N/A
A13: Batch ID: | B13: DEN078 | J13: TE (1X) buffer (pH8.0) or suitable alternative | M13: Fisher Scientific | N13: 10224683 | O13: 250226
A14: Operator: | B14: KP
A15: Date: | B15: 45992
B17: Equipment Used
B19: Asset # | C19: Item | G19: Make | I19: Model | K19: Serial number
B20: 60 | C20: Laminar Flow Cabinet | G20: StarLab | I20: GuardOne | K20: 9206IL 200028
B21: 00131 | C21: PCR machine | G21: AppliedBiosystems | I21: QuantStudio 1 | K21: 2721224090023
B22: 64 | C22: PCR machine | G22: Roche | I22: LightCycler 480 II, 96 | K22: 32258
B23: 73 | C23: Mini Vortexer | G23: Heathrow Scientific | I23: 120567 | K23: HSA09547
B24: 74 | C24: MiniSpin | G24: Eppendorf | I24: Various | K24: 5452HR504062.
B25: 98 | C25: Axygen Plate Centrifuge | G25: Corning | I25: Various | K25: 22132009
B26: 89 | C26: BioShaker iQ | G26: Qinstrument | I26: BioShaker iQ | K26: 26656
B28: Note: Throughout workbook, editable fields are denoted by yellow highlighting.

Sheet Sample List
A1: =IF('LC Raw Results'!A2>1, RIGHT('LC Raw Results'!A2, LEN('LC Raw Results'!A2)-12), IF('QS Raw Results'!A25>1, INDEX(_xlfn.TEXTSPLIT('QS Raw Results'!A25,"\"),1,7), "Paste Results File into Cell A2 of LC Raw Results or QS Raw Results")) -> 2025-11-05_095412_DEN078_RNaseP-16S.eds
B3: Sample Information | F3: Workbook Assumed Sample Positions/Layout
B5: Sample No. | C5: Sample Barcode/ID | G5: 1 | H5: 2 | I5: 3 | J5: 4 | K5: 5 | L5: 6 | M5: 7 | N5: 8 | O5: 9 | P5: 10 | Q5: 11 | R5: 12
B6: 1 | C6: PD005745RME2_D_Hu_01 | F6: A | G6: Standard 1 | J6: 1 | M6: 9 | P6: 17
B7: 2 | C7: PD005599RME1_D_Hu_01 | F7: B | G7: Standard 2 | J7: 2 | M7: 10 | P7: 18
B8: 3 | C8: PD005595RME1_D_Hu_01 | F8: C | G8: Standard 3 | J8: 3 | M8: 11 | P8: 19
B9: 4 | C9: PD005590RME1_D_Hu_01 | F9: D | G9: Standard 4 | J9: 4 | M9: 12 | P9: 20
B10: 5 | C10: PD005585RME1_D_Hu_01 | F10: E | G10: Standard 5 | J10: 5 | M10: 13 | P10: 21
B11: 6 | C11: PD005594RME1_D_Hu_01 | F11: F | G11: Standard 6 | J11: 6 | M11: 14 | P11: 22
B12: 7 | C12: PD005593RME1_D_Hu_01 | F12: G | G12: POS Control | J12: 7 | M12: 15 | P12: 23
B13: 8 | C13: PD005592RME1_D_Hu_01 | F13: H | G13: NEG Control | J13: 8 | M13: 16 | P13: 24
B14: 9 | C14: PD005584RME1_D_Hu_01
B15: 10 | C15: PD005578RME1_D_Hu_01
B16: 11 | C16: PD005575RME1_D_Hu_01
B17: 12 | C17: PD005572RME1_D_Hu_01
B18: 13 | C18: PD005571RME1_D_Hu_01
B19: 14 | C19: PD005568RME1_D_Hu_01
B20: 15 | C20: PD005565RME1_D_Hu_01
B21: 16 | C21: PD005564RME4_D_Hu_01
B22: 17 | C22: PD005563RME1_D_Hu_01
B23: 18 | C23: PD005562RME1_D_Hu_01
B24: 19 | C24: PD005561RME1_D_Hu_01
B25: 20 | C25: PD005558RME1_D_Hu_01
... B29: 24 | C29: DEN078-NEG_D_Hu_01
B30: POS Control | C30: Human Male DNA 10ng/uL
B31: NEG Control | C31: NF-Water

Sheet Standards
A1: =IF('LC Raw Results'!A2>1, RIGHT('LC Raw Results'!A2, LEN('LC Raw Results'!A2)-12), IF('QS Raw Results'!A25>1, INDEX(_xlfn.TEXTSPLIT('QS Raw Results'!A25,"\"),1,7), "Paste Results File into Cell A2 of LC Raw Results or QS Raw Results")) -> 2025-11-05_095412_DEN078_RNaseP-16S.eds
B3: PCR Standard Curve Preparation
B6: RNase P Standard Curve Preparation
B7: Human Genomic DNA Stock Concentration (µg/mL): | G7: 209
B9: Calculations for Standard Curve Preparation: | M9: Optimal (Theoretical) Standard Curve:
C10: Volumes Required (uL) | I10: Final Concentration (pg/µl or ng/mL) | N10: Final Concentration (pg/µL or ng/mL)
B11: Standard | C11: Previous Dilution | E11: Diluent (TE Buffer) | G11: Total* | M11: Standard
B12: S1 | C12: =IF(ISODD(RIGHT(FIXED((N12/(G7*1000)*20),2),1))=TRUE,SUM((FIXED((N12/(G7*1000)*20),2))+0.01),FIXED((N12/(G7*1000)*20),2))&" (Stock)" -> 14.36 (Stock) | E12: =FIXED(20-(IF(ISODD(RIGHT(FIXED((N12/(G7*1000)*20),2),1))=TRUE,SUM((FIXED((N12/(G7*1000)*20),2))+0.01),FIXED((N12/(G7*1000)*20),2))),2) -> 5.64 | G12: 20 | I12: =(LEFT(C12,5)/20)*($G$7*1000) -> 150062 | M12: S1 | N12: 150000
B13: S2 | C13: 4.50 (S1) | E13: 15.5 | G13: 20 | I13: =(4.5/20)*I12 -> 33763.95 | M13: S2 | N13: =(4.5/20)*N12 -> 33750
B14: S3 | C14: 4.50 (S2) | E14: 15.5 | G14: 20 | I14: =(4.5/20)*I13 -> 7596.8888 | M14: S3 | N14: =(4.5/20)*N13 -> 7593.75
B15: S4 | C15: 4.50 (S3) | E15: 15.5 | G15: 20 | I15: =(4.5/20)*I14 -> 1709.3 | M15: S4 | N15: =(4.5/20)*N14 -> 1708.5938
B16: S5 | C16: 4.50 (S4) | E16: 15.5 | G16: 20 | I16: =(4.5/20)*I15 -> 384.59249 | M16: S5 | N16: =(4.5/20)*N15 -> 384.43359
B17: S6 | C17: 4.50 (S5) | E17: 15.5 | G17: 20 | I17: =(4.5/20)*I16 -> 86.533311 | M17: S6 | N17: =(4.5/20)*N16 -> 86.497559
B18: *Prior to using 4.5uL to prepare the next sequential standard.
B20: Note:
B21: p20 pipette has mininum changeable unit of 0.02 leading to very small changes in concentration. This is factored in to produce above table.
B26: 16S Standard Curve Preparation
B27: Dilute Microbial Community DNA Standard to a Concentration of 20000ng/mL Prior to Preparing Curve - This is added as the First Standard
B29: Calculations for Standard Curve Preparation:
C30: Volumes Required (uL) | I30: Theoretical Concentration (pg/µl)
B31: Standard | C31: Previous Dilution | E31: Diluent (TE Buffer) | G31: Total*
B32: S1 | C32: 16.00 (Stock) | E32: 0 | G32: 16 | I32: 20000
B33: S2 | C33: 2.00 (S1) | E33: 14 | G33: 16 | I33: 2500
B34: S3 | C34: 2.00 (S2) | E34: 14 | G34: 16 | I34: 312.5
B35: S4 | C35: 2.00 (S3) | E35: 14 | G35: 16 | I35: 39.06
B36: S5 | C36: 2.00 (S4) | E36: 14 | G36: 16 | I36: 4.88
B37: S6 | C37: 2.00 (S5) | E37: 14 | G37: 16 | I37: 0.61
B38: *Prior to using 2uL to prepare the next sequential standard.
B40: Note:
B41: For the NTC, add the diluent used for these standards

Sheet qPCR Setup
A1: =IF('LC Raw Results'!A2>1, RIGHT('LC Raw Results'!A2, LEN('LC Raw Results'!A2)-12), IF('QS Raw Results'!A25>1, INDEX(_xlfn.TEXTSPLIT('QS Raw Results'!A25,"\"),1,7), "Paste Results File into Cell A2 of LC Raw Results or QS Raw Results")) -> 2025-11-05_095412_DEN078_RNaseP-16S.eds
B3: Plate Layout for qPCR | Q3: Master Mix Calculations
Q5: Number of Samples: | S5: 24
B6: Standards Plated in Triplicate, Test Samples (1-24) Plated in Triplicate and Diluted 1 in 20:
Q7: Component | T7: Stock Conc. | V7: Reaction Conc. | X7: Per Well (uL) | Z7: Standards / Controls (uL) | AA7: Total Required* (uL)
C8: 1 | D8: 2 | E8: 3 | F8: 4 | G8: 5 | H8: 6 | I8: 7 | J8: 8 | K8: 9 | L8: 10 | M8: 11 | N8: 12 | AA8: Required | AB8: (+10%)
B9: A | C9: S1 | F9: 1 (1 in 20) | I9: 9 (1 in 20) | L9: 17 (1 in 20) | Q9: Fast Advanced Master Mix | T9: 2x | V9: 1x | X9: 10 | Z9: =X9*24 -> 240 | AA9: =Z9+(3*(X9*$S$5)) -> 960 | AB9: =AA9*1.1 -> 1056
B10: B | C10: S2 | F10: 2 (1 in 20) | I10: 10 (1 in 20) | L10: 18 (1 in 20) | Q10: RNase P Primer-Probe (FAM) | T10: 20x | V10: 1x | X10: 0.5 | Z10: =X10*24 -> 12 | AA10: =Z10+(3*(X10*$S$5)) -> 48 | AB10: =AA10*1.1 -> 52.8
B11: C | C11: S3 | F11: 3 (1 in 20) | I11: 11 (1 in 20) | L11: 19 (1 in 20) | Q11: 16S Primer-Probe (VIC) | T11: 20x | V11: 1x | X11: 1 | Z11: =X11*24 -> 24 | AA11: =Z11+(3*(X11*$S$5)) -> 96 | AB11: =AA11*1.1 -> 105.6
B12: D | C12: S4 | F12: 4 (1 in 20) | I12: 12 (1 in 20) | L12: 20 (1 in 20) | Q12: TE Buffer/NF-Water | T12: N/A | V12: N/A | X12: 4.5 | Z12: =X12*24 -> 108 | AA12: =Z12+(3*(X12*$S$5)) -> 432 | AB12: =AA12*1.1 -> 475.2
B13: E | C13: S5 | F13: 5 (1 in 20) | I13: 13 (1 in 20) | L13: 21 (1 in 20) | W13: Totals: | X13: =SUM(X9:Y12) -> 16 | Z13: =SUM(Z9:Z12) -> 384 | AA13: =SUM(AA9:AA12) -> 1536 | AB13: =SUM(AB9:AB12) -> 1689.6
B14: F | C14: S6 | F14: 6 (1 in 20) | I14: 14 (1 in 20) | L14: 22 (1 in 20) | X14: *Total Required Including Standards
B15: G | C15: Human DNA Male - 10ng/µL | F15: 7 (1 in 20) | I15: 15 (1 in 20) | L15: 23 (1 in 20)
B16: H | C16: NTC | F16: 8 (1 in 20) | I16: 16 (1 in 20) | L16: 24 (1 in 20)
Q18: Cycling Conditions on PCR machine
Q20: Step | S20: Temperature | U20: Time | W20: # Cycles
Q21: UNG Incubation | S21: 50˚C | U21: 2 Minutes | W21: 1
Q22: Enzyme Activation | S22: 95˚C | U22: 20 Seconds | W22: 1
Q23: Denaturation | S23: 95˚C | U23: 1 Second | W23: 45
Q24: Anneal/Extension | S24: 60˚C | U24: 20 Seconds

Sheet LC Raw Results
A1: =IF('LC Raw Results'!A2>1, RIGHT('LC Raw Results'!A2, LEN('LC Raw Results'!A2)-12), "Select All in .txt Export File and Paste into Cell A2") -> Select All in .txt Export File and Paste into Cell A2

Sheet LC Calculations
B3: Plate Map | P3: Standards | Y3: Options
Y4: PCR1
C5: 1 | D5: 2 | E5: 3 | F5: 4 | G5: 5 | H5: 6 | I5: 7 | J5: 8 | K5: 9 | L5: 10 | M5: 11 | N5: 12 | P5: Sample | Q5: Cp1 | R5: Cp2 | S5: Cp3 | T5: Mean Cp | U5: SEM | W5: LC Conc. Mean | Y5: PCR2 | AA5: Calculated Mean Concs: | AD5: Conc. Used:
B6: A | C6: A1 | D6: A2 | E6: A3 | F6: A4 | G6: A5 | H6: A6 | I6: A7 | J6: A8 | K6: A9 | L6: A10 | M6: A11 | N6: A12 | P6: Std. 1 | Q6: {=_xlfn.ANCHORARRAY(C18)} -> #VALUE! | T6: =IFERROR(AVERAGEIF(_xlfn.ANCHORARRAY(Q6),"<>0"),0) -> 0 | U6: =IFERROR((_xlfn.STDEV.P(Q6:S6)/SQRT(3)),0) -> 0 | W6: =AVERAGE(_xlfn.ANCHORARRAY(C30)) -> #VALUE! | AA6: =IF(T6=0,0,10^((T6-'LC Analysis'!$V$37)/'LC Analysis'!$V$38)) -> 0 | AD6: =IF($Y$17="Yes",W6,AA6) -> 0
B7: B | C7: B1 | D7: B2 | E7: B3 | F7: B4 | G7: B5 | H7: B6 | I7: B7 | J7: B8 | K7: B9 | L7: B10 | M7: B11 | N7: B12 | P7: Std. 2 | Q7: {=_xlfn.ANCHORARRAY(C19)} -> #VALUE! | T7: =IFERROR(AVERAGEIF(_xlfn.ANCHORARRAY(Q7),"<>0"),0) -> 0 | U7: =IFERROR((_xlfn.STDEV.P(Q7:S7)/SQRT(3)),0) -> 0 | W7: =AVERAGE(_xlfn.ANCHORARRAY(C31)) -> #VALUE! | AA7: =IF(T7=0,0,10^((T7-'LC Analysis'!$V$37)/'LC Analysis'!$V$38)) -> 0 | AD7: =IF($Y$17="Yes",W7,AA7) -> 0
B8: C | C8: C1 | D8: C2 | E8: C3 | F8: C4 | G8: C5 | H8: C6 | I8: C7 | J8: C8 | K8: C9 | L8: C10 | M8: C11 | N8: C12 | P8: Std. 3 | Q8: {=_xlfn.ANCHORARRAY(C20)} -> #VALUE! | T8: =IFERROR(AVERAGEIF(_xlfn.ANCHORARRAY(Q8),"<>0"),0) -> 0 | U8: =IFERROR((_xlfn.STDEV.P(Q8:S8)/SQRT(3)),0) -> 0 | W8: =AVERAGE(_xlfn.ANCHORARRAY(C32)) -> #VALUE! | AA8: =IF(T8=0,0,10^((T8-'LC Analysis'!$V$37)/'LC Analysis'!$V$38)) -> 0 | AD8: =IF($Y$17="Yes",W8,AA8) -> 0
B9: D | C9: D1 | D9: D2 | E9: D3 | F9: D4 | G9: D5 | H9: D6 | I9: D7 | J9: D8 | K9: D9 | L9: D10 | M9: D11 | N9: D12 | P9: Std. 4 | Q9: {=_xlfn.ANCHORARRAY(C21)} -> #VALUE! | T9: =IFERROR(AVERAGEIF(_xlfn.ANCHORARRAY(Q9),"<>0"),0) -> 0 | U9: =IFERROR((_xlfn.STDEV.P(Q9:S9)/SQRT(3)),0) -> 0 | W9: =AVERAGE(_xlfn.ANCHORARRAY(C33)) -> #VALUE! | AA9: =IF(T9=0,0,10^((T9-'LC Analysis'!$V$37)/'LC Analysis'!$V$38)) -> 0 | AD9: =IF($Y$17="Yes",W9,AA9) -> 0
B10: E | C10: E1 | D10: E2 | E10: E3 | F10: E4 | G10: E5 | H10: E6 | I10: E7 | J10: E8 | K10: E9 | L10: E10 | M10: E11 | N10: E12 | P10: Std. 5 | Q10: {=_xlfn.ANCHORARRAY(C22)} -> #VALUE! | T10: =IFERROR(AVERAGEIF(_xlfn.ANCHORARRAY(Q10),"<>0"),0) -> 0 | U10: =IFERROR((_xlfn.STDEV.P(Q10:S10)/SQRT(3)),0) -> 0 | W10: =AVERAGE(_xlfn.ANCHORARRAY(C34)) -> #VALUE! | AA10: =IF(T10=0,0,10^((T10-'LC Analysis'!$V$37)/'LC Analysis'!$V$38)) -> 0 | AD10: =IF($Y$17="Yes",W10,AA10) -> 0
B11: F | C11: F1 | D11: F2 | E11: F3 | F11: F4 | G11: F5 | H11: F6 | I11: F7 | J11: F8 | K11: F9 | L11: F10 | M11: F11 | N11: F12 | P11: Std. 6 | Q11: {=_xlfn.ANCHORARRAY(C23)} -> #VALUE! | T11: =IFERROR(AVERAGEIF(_xlfn.ANCHORARRAY(Q11),"<>0"),0) -> 0 | U11: =IFERROR((_xlfn.STDEV.P(Q11:S11)/SQRT(3)),0) -> 0 | W11: =AVERAGE(_xlfn.ANCHORARRAY(C35)) -> #VALUE! | AA11: =IF(T11=0,0,10^((T11-'LC Analysis'!$V$37)/'LC Analysis'!$V$38)) -> 0 | AD11: =IF($Y$17="Yes",W11,AA11) -> 0
B12: G | C12: G1 | D12: G2 | E12: G3 | F12: G4 | G12: G5 | H12: G6 | I12: G7 | J12: G8 | K12: G9 | L12: G10 | M12: G11 | N12: G12 | P12: HuMale | Q12: {=_xlfn.ANCHORARRAY(C24)} -> #VALUE! | T12: =IFERROR(AVERAGEIF(_xlfn.ANCHORARRAY(Q12),"<>0"),0) -> 0 | U12: =IFERROR((_xlfn.STDEV.P(Q12:S12)/SQRT(3)),0) -> 0 | W12: =AVERAGE(_xlfn.ANCHORARRAY(C36)) -> #VALUE! | AA12: =IF(T12=0,0,10^((T12-'LC Analysis'!$V$37)/'LC Analysis'!$V$38)) -> 0 | AD12: =IF($Y$17="Yes",W12,AA12) -> 0
B13: H | C13: H1 | D13: H2 | E13: H3 | F13: H4 | G13: H5 | H13: H6 | I13: H7 | J13: H8 | K13: H9 | L13: H10 | M13: H11 | N13: H12 | P13: NTC | Q13: {=_xlfn.ANCHORARRAY(C25)} -> #VALUE! | T13: =IFERROR(AVERAGEIF(_xlfn.ANCHORARRAY(Q13),"<>0"),0) -> 0 | U13: =IFERROR((_xlfn.STDEV.P(Q13:S13)/SQRT(3)),0) -> 0 | W13: =AVERAGE(_xlfn.ANCHORARRAY(C37)) -> #VALUE! | AA13: =IF(T13=0,0,10^((T13-'LC Analysis'!$V$37)/'LC Analysis'!$V$38)) -> 0 | AD13: =IF($Y$17="Yes",W13,AA13) -> 0
B15: Cps | P15: Samples
Y16: LC Concs?
C17: 1 | D17: 2 | E17: 3 | F17: 4 | G17: 5 | H17: 6 | I17: 7 | J17: 8 | K17: 9 | L17: 10 | M17: 11 | N17: 12 | P17: Sample | Q17: Cp1 | R17: Cp2 | S17: Cp3 | T17: Mean Cp | U17: SEM | W17: LC Conc. Mean | Y17: =IF(SUM(_xlfn._xlws.FILTER('LC Raw Results'!F4:F6,1))=0,"No","Yes") -> No | AA17: Calculated Mean Concs: | AD17: Conc. Used:
B18: A | C18: {=TRANSPOSE(_xlfn._xlws.FILTER('LC Raw Results'!$E:$E,('LC Raw Results'!$C:$C='LC Calculations'!C6)+('LC Raw Results'!$C:$C='LC Calculations'!D6)+('LC Raw Results'!$C:$C='LC Calculations'!E6)))} -> #VALUE! | F18: {=TRANSPOSE(_xlfn._xlws.FILTER('LC Raw Results'!$E:$E,('LC Raw Results'!$C:$C='LC Calculations'!F6)+('LC Raw Results'!$C:$C='LC Calculations'!G6)+('LC Raw Results'!$C:$C='LC Calculations'!H6)))} -> #VALUE! | I18: {=TRANSPOSE(_xlfn._xlws.FILTER('LC Raw Results'!$E:$E,('LC Raw Results'!$C:$C='LC Calculations'!I6)+('LC Raw Results'!$C:$C='LC Calculations'!J6)+('LC Raw Results'!$C:$C='LC Calculations'!K6)))} -> #VALUE! | L18: {=TRANSPOSE(_xlfn._xlws.FILTER('LC Raw Results'!$E:$E,('LC Raw Results'!$C:$C='LC Calculations'!L6)+('LC Raw Results'!$C:$C='LC Calculations'!M6)+('LC Raw Results'!$C:$C='LC Calculations'!N6)))} -> #VALUE! | P18: 1 | Q18: {=_xlfn.ANCHORARRAY(F18)} -> #VALUE! | T18: =IFERROR(AVERAGEIF(_xlfn.ANCHORARRAY(Q18),"<>0"),0) -> 0 | U18: =IFERROR((_xlfn.STDEV.P(Q18:S18)/SQRT(3)),0) -> 0 | W18: =AVERAGE(_xlfn.ANCHORARRAY(F30)) -> #VALUE! | AA18: =IF(T18=0,0,10^((T18-'LC Analysis'!$V$37)/'LC Analysis'!$V$38)) -> 0 | AD18: =IF($Y$17="Yes",W18,AA18) -> 0
B19: B | C19: {=TRANSPOSE(_xlfn._xlws.FILTER('LC Raw Results'!$E:$E,('LC Raw Results'!$C:$C='LC Calculations'!C7)+('LC Raw Results'!$C:$C='LC Calculations'!D7)+('LC Raw Results'!$C:$C='LC Calculations'!E7)))} -> #VALUE! | F19: {=TRANSPOSE(_xlfn._xlws.FILTER('LC Raw Results'!$E:$E,('LC Raw Results'!$C:$C='LC Calculations'!F7)+('LC Raw Results'!$C:$C='LC Calculations'!G7)+('LC Raw Results'!$C:$C='LC Calculations'!H7)))} -> #VALUE! | I19: {=TRANSPOSE(_xlfn._xlws.FILTER('LC Raw Results'!$E:$E,('LC Raw Results'!$C:$C='LC Calculations'!I7)+('LC Raw Results'!$C:$C='LC Calculations'!J7)+('LC Raw Results'!$C:$C='LC Calculations'!K7)))} -> #VALUE! | L19: {=TRANSPOSE(_xlfn._xlws.FILTER('LC Raw Results'!$E:$E,('LC Raw Results'!$C:$C='LC Calculations'!L7)+('LC Raw Results'!$C:$C='LC Calculations'!M7)+('LC Raw Results'!$C:$C='LC Calculations'!N7)))} -> #VALUE! | P19: 2 | Q19: {=_xlfn.ANCHORARRAY(F19)} -> #VALUE! | T19: =IFERROR(AVERAGEIF(_xlfn.ANCHORARRAY(Q19),"<>0"),0) -> 0 | U19: =IFERROR((_xlfn.STDEV.P(Q19:S19)/SQRT(3)),0) -> 0 | W19: =AVERAGE(_xlfn.ANCHORARRAY(F31)) -> #VALUE! | AA19: =IF(T19=0,0,10^((T19-'LC Analysis'!$V$37)/'LC Analysis'!$V$38)) -> 0 | AD19: =IF($Y$17="Yes",W19,AA19) -> 0
B20: C | C20: {=TRANSPOSE(_xlfn._xlws.FILTER('LC Raw Results'!$E:$E,('LC Raw Results'!$C:$C='LC Calculations'!C8)+('LC Raw Results'!$C:$C='LC Calculations'!D8)+('LC Raw Results'!$C:$C='LC Calculations'!E8)))} -> #VALUE! | F20: {=TRANSPOSE(_xlfn._xlws.FILTER('LC Raw Results'!$E:$E,('LC Raw Results'!$C:$C='LC Calculations'!F8)+('LC Raw Results'!$C:$C='LC Calculations'!G8)+('LC Raw Results'!$C:$C='LC Calculations'!H8)))} -> #VALUE! | I20: {=TRANSPOSE(_xlfn._xlws.FILTER('LC Raw Results'!$E:$E,('LC Raw Results'!$C:$C='LC Calculations'!I8)+('LC Raw Results'!$C:$C='LC Calculations'!J8)+('LC Raw Results'!$C:$C='LC Calculations'!K8)))} -> #VALUE! | L20: {=TRANSPOSE(_xlfn._xlws.FILTER('LC Raw Results'!$E:$E,('LC Raw Results'!$C:$C='LC Calculations'!L8)+('LC Raw Results'!$C:$C='LC Calculations'!M8)+('LC Raw Results'!$C:$C='LC Calculations'!N8)))} -> #VALUE! | P20: 3 | Q20: {=_xlfn.ANCHORARRAY(F20)} -> #VALUE! | T20: =IFERROR(AVERAGEIF(_xlfn.ANCHORARRAY(Q20),"<>0"),0) -> 0 | U20: =IFERROR((_xlfn.STDEV.P(Q20:S20)/SQRT(3)),0) -> 0 | W20: =AVERAGE(_xlfn.ANCHORARRAY(F32)) -> #VALUE! | AA20: =IF(T20=0,0,10^((T20-'LC Analysis'!$V$37)/'LC Analysis'!$V$38)) -> 0 | AD20: =IF($Y$17="Yes",W20,AA20) -> 0
B21: D | C21: {=TRANSPOSE(_xlfn._xlws.FILTER('LC Raw Results'!$E:$E,('LC Raw Results'!$C:$C='LC Calculations'!C9)+('LC Raw Results'!$C:$C='LC Calculations'!D9)+('LC Raw Results'!$C:$C='LC Calculations'!E9)))} -> #VALUE! | F21: {=TRANSPOSE(_xlfn._xlws.FILTER('LC Raw Results'!$E:$E,('LC Raw Results'!$C:$C='LC Calculations'!F9)+('LC Raw Results'!$C:$C='LC Calculations'!G9)+('LC Raw Results'!$C:$C='LC Calculations'!H9)))} -> #VALUE! | I21: {=TRANSPOSE(_xlfn._xlws.FILTER('LC Raw Results'!$E:$E,('LC Raw Results'!$C:$C='LC Calculations'!I9)+('LC Raw Results'!$C:$C='LC Calculations'!J9)+('LC Raw Results'!$C:$C='LC Calculations'!K9)))} -> #VALUE! | L21: {=TRANSPOSE(_xlfn._xlws.FILTER('LC Raw Results'!$E:$E,('LC Raw Results'!$C:$C='LC Calculations'!L9)+('LC Raw Results'!$C:$C='LC Calculations'!M9)+('LC Raw Results'!$C:$C='LC Calculations'!N9)))} -> #VALUE! | P21: 4 | Q21: {=_xlfn.ANCHORARRAY(F21)} -> #VALUE! | T21: =IFERROR(AVERAGEIF(_xlfn.ANCHORARRAY(Q21),"<>0"),0) -> 0 | U21: =IFERROR((_xlfn.STDEV.P(Q21:S21)/SQRT(3)),0) -> 0 | W21: =AVERAGE(_xlfn.ANCHORARRAY(F33)) -> #VALUE! | AA21: =IF(T21=0,0,10^((T21-'LC Analysis'!$V$37)/'LC Analysis'!$V$38)) -> 0 | AD21: =IF($Y$17="Yes",W21,AA21) -> 0
B22: E | C22: {=TRANSPOSE(_xlfn._xlws.FILTER('LC Raw Results'!$E:$E,('LC Raw Results'!$C:$C='LC Calculations'!C10)+('LC Raw Results'!$C:$C='LC Calculations'!D10)+('LC Raw Results'!$C:$C='LC Calculations'!E10)))} -> #VALUE! | F22: {=TRANSPOSE(_xlfn._xlws.FILTER('LC Raw Results'!$E:$E,('LC Raw Results'!$C:$C='LC Calculations'!F10)+('LC Raw Results'!$C:$C='LC Calculations'!G10)+('LC Raw Results'!$C:$C='LC Calculations'!H10)))} -> #VALUE! | I22: {=TRANSPOSE(_xlfn._xlws.FILTER('LC Raw Results'!$E:$E,('LC Raw Results'!$C:$C='LC Calculations'!I10)+('LC Raw Results'!$C:$C='LC Calculations'!J10)+('LC Raw Results'!$C:$C='LC Calculations'!K10)))} -> #VALUE! | L22: {=TRANSPOSE(_xlfn._xlws.FILTER('LC Raw Results'!$E:$E,('LC Raw Results'!$C:$C='LC Calculations'!L10)+('LC Raw Results'!$C:$C='LC Calculations'!M10)+('LC Raw Results'!$C:$C='LC Calculations'!N10)))} -> #VALUE! | P22: 5 | Q22: {=_xlfn.ANCHORARRAY(F22)} -> #VALUE! | T22: =IFERROR(AVERAGEIF(_xlfn.ANCHORARRAY(Q22),"<>0"),0) -> 0 | U22: =IFERROR((_xlfn.STDEV.P(Q22:S22)/SQRT(3)),0) -> 0 | W22: =AVERAGE(_xlfn.ANCHORARRAY(F34)) -> #VALUE! | AA22: =IF(T22=0,0,10^((T22-'LC Analysis'!$V$37)/'LC Analysis'!$V$38)) -> 0 | AD22: =IF($Y$17="Yes",W22,AA22) -> 0
B23: F | C23: {=TRANSPOSE(_xlfn._xlws.FILTER('LC Raw Results'!$E:$E,('LC Raw Results'!$C:$C='LC Calculations'!C11)+('LC Raw Results'!$C:$C='LC Calculations'!D11)+('LC Raw Results'!$C:$C='LC Calculations'!E11)))} -> #VALUE! | F23: {=TRANSPOSE(_xlfn._xlws.FILTER('LC Raw Results'!$E:$E,('LC Raw Results'!$C:$C='LC Calculations'!F11)+('LC Raw Results'!$C:$C='LC Calculations'!G11)+('LC Raw Results'!$C:$C='LC Calculations'!H11)))} -> #VALUE! | I23: {=TRANSPOSE(_xlfn._xlws.FILTER('LC Raw Results'!$E:$E,('LC Raw Results'!$C:$C='LC Calculations'!I11)+('LC Raw Results'!$C:$C='LC Calculations'!J11)+('LC Raw Results'!$C:$C='LC Calculations'!K11)))} -> #VALUE! | L23: {=TRANSPOSE(_xlfn._xlws.FILTER('LC Raw Results'!$E:$E,('LC Raw Results'!$C:$C='LC Calculations'!L11)+('LC Raw Results'!$C:$C='LC Calculations'!M11)+('LC Raw Results'!$C:$C='LC Calculations'!N11)))} -> #VALUE! | P23: 6 | Q23: {=_xlfn.ANCHORARRAY(F23)} -> #VALUE! | T23: =IFERROR(AVERAGEIF(_xlfn.ANCHORARRAY(Q23),"<>0"),0) -> 0 | U23: =IFERROR((_xlfn.STDEV.P(Q23:S23)/SQRT(3)),0) -> 0 | W23: =AVERAGE(_xlfn.ANCHORARRAY(F35)) -> #VALUE! | AA23: =IF(T23=0,0,10^((T23-'LC Analysis'!$V$37)/'LC Analysis'!$V$38)) -> 0 | AD23: =IF($Y$17="Yes",W23,AA23) -> 0
B24: G | C24: {=TRANSPOSE(_xlfn._xlws.FILTER('LC Raw Results'!$E:$E,('LC Raw Results'!$C:$C='LC Calculations'!C12)+('LC Raw Results'!$C:$C='LC Calculations'!D12)+('LC Raw Results'!$C:$C='LC Calculations'!E12)))} -> #VALUE! | F24: {=TRANSPOSE(_xlfn._xlws.FILTER('LC Raw Results'!$E:$E,('LC Raw Results'!$C:$C='LC Calculations'!F12)+('LC Raw Results'!$C:$C='LC Calculations'!G12)+('LC Raw Results'!$C:$C='LC Calculations'!H12)))} -> #VALUE! | I24: {=TRANSPOSE(_xlfn._xlws.FILTER('LC Raw Results'!$E:$E,('LC Raw Results'!$C:$C='LC Calculations'!I12)+('LC Raw Results'!$C:$C='LC Calculations'!J12)+('LC Raw Results'!$C:$C='LC Calculations'!K12)))} -> #VALUE! | L24: {=TRANSPOSE(_xlfn._xlws.FILTER('LC Raw Results'!$E:$E,('LC Raw Results'!$C:$C='LC Calculations'!L12)+('LC Raw Results'!$C:$C='LC Calculations'!M12)+('LC Raw Results'!$C:$C='LC Calculations'!N12)))} -> #VALUE! | P24: 7 | Q24: {=_xlfn.ANCHORARRAY(F24)} -> #VALUE! | T24: =IFERROR(AVERAGEIF(_xlfn.ANCHORARRAY(Q24),"<>0"),0) -> 0 | U24: =IFERROR((_xlfn.STDEV.P(Q24:S24)/SQRT(3)),0) -> 0 | W24: =AVERAGE(_xlfn.ANCHORARRAY(F36)) -> #VALUE! | AA24: =IF(T24=0,0,10^((T24-'LC Analysis'!$V$37)/'LC Analysis'!$V$38)) -> 0 | AD24: =IF($Y$17="Yes",W24,AA24) -> 0
B25: H | C25: {=TRANSPOSE(_xlfn._xlws.FILTER('LC Raw Results'!$E:$E,('LC Raw Results'!$C:$C='LC Calculations'!C13)+('LC Raw Results'!$C:$C='LC Calculations'!D13)+('LC Raw Results'!$C:$C='LC Calculations'!E13)))} -> #VALUE! | F25: {=TRANSPOSE(_xlfn._xlws.FILTER('LC Raw Results'!$E:$E,('LC Raw Results'!$C:$C='LC Calculations'!F13)+('LC Raw Results'!$C:$C='LC Calculations'!G13)+('LC Raw Results'!$C:$C='LC Calculations'!H13)))} -> #VALUE! | I25: {=TRANSPOSE(_xlfn._xlws.FILTER('LC Raw Results'!$E:$E,('LC Raw Results'!$C:$C='LC Calculations'!I13)+('LC Raw Results'!$C:$C='LC Calculations'!J13)+('LC Raw Results'!$C:$C='LC Calculations'!K13)))} -> #VALUE! | L25: {=TRANSPOSE(_xlfn._xlws.FILTER('LC Raw Results'!$E:$E,('LC Raw Results'!$C:$C='LC Calculations'!L13)+('LC Raw Results'!$C:$C='LC Calculations'!M13)+('LC Raw Results'!$C:$C='LC Calculations'!N13)))} -> #VALUE! | P25: 8 | Q25: {=_xlfn.ANCHORARRAY(F25)} -> #VALUE! | T25: =IFERROR(AVERAGEIF(_xlfn.ANCHORARRAY(Q25),"<>0"),0) -> 0 | U25: =IFERROR((_xlfn.STDEV.P(Q25:S25)/SQRT(3)),0) -> 0 | W25: =AVERAGE(_xlfn.ANCHORARRAY(F37)) -> #VALUE! | AA25: =IF(T25=0,0,10^((T25-'LC Analysis'!$V$37)/'LC Analysis'!$V$38)) -> 0 | AD25: =IF($Y$17="Yes",W25,AA25) -> 0
P26: 9 | Q26: {=_xlfn.ANCHORARRAY(I18)} -> #VALUE! | T26: =IFERROR(AVERAGEIF(_xlfn.ANCHORARRAY(Q26),"<>0"),0) -> 0 | U26: =IFERROR((_xlfn.STDEV.P(Q26:S26)/SQRT(3)),0) -> 0 | W26: =AVERAGE(_xlfn.ANCHORARRAY(I30)) -> #VALUE! | AA26: =IF(T26=0,0,10^((T26-'LC Analysis'!$V$37)/'LC Analysis'!$V$38)) -> 0 | AD26: =IF($Y$17="Yes",W26,AA26) -> 0
B27: Concentrations | P27: 10 | Q27: {=_xlfn.ANCHORARRAY(I19)} -> #VALUE! | T27: =IFERROR(AVERAGEIF(_xlfn.ANCHORARRAY(Q27),"<>0"),0) -> 0 | U27: =IFERROR((_xlfn.STDEV.P(Q27:S27)/SQRT(3)),0) -> 0 | W27: =AVERAGE(_xlfn.ANCHORARRAY(I31)) -> #VALUE! | AA27: =IF(T27=0,0,10^((T27-'LC Analysis'!$V$37)/'LC Analysis'!$V$38)) -> 0 | AD27: =IF($Y$17="Yes",W27,AA27) -> 0
P28: 11 | Q28: {=_xlfn.ANCHORARRAY(I20)} -> #VALUE! | T28: =IFERROR(AVERAGEIF(_xlfn.ANCHORARRAY(Q28),"<>0"),0) -> 0 | U28: =IFERROR((_xlfn.STDEV.P(Q28:S28)/SQRT(3)),0) -> 0 | W28: =AVERAGE(_xlfn.ANCHORARRAY(I32)) -> #VALUE! | AA28: =IF(T28=0,0,10^((T28-'LC Analysis'!$V$37)/'LC Analysis'!$V$38)) -> 0 | AD28: =IF($Y$17="Yes",W28,AA28) -> 0
C29: 1 | D29: 2 | E29: 3 | F29: 4 | G29: 5 | H29: 6 | I29: 7 | J29: 8 | K29: 9 | L29: 10 | M29: 11 | N29: 12 | P29: 12 | Q29: {=_xlfn.ANCHORARRAY(I21)} -> #VALUE! | T29: =IFERROR(AVERAGEIF(_xlfn.ANCHORARRAY(Q29),"<>0"),0) -> 0 | U29: =IFERROR((_xlfn.STDEV.P(Q29:S29)/SQRT(3)),0) -> 0 | W29: =AVERAGE(_xlfn.ANCHORARRAY(I33)) -> #VALUE! | AA29: =IF(T29=0,0,10^((T29-'LC Analysis'!$V$37)/'LC Analysis'!$V$38)) -> 0 | AD29: =IF($Y$17="Yes",W29,AA29) -> 0
B30: A | C30: {=TRANSPOSE(_xlfn._xlws.FILTER('LC Raw Results'!$F:$F,('LC Raw Results'!$C:$C='LC Calculations'!C6)+('LC Raw Results'!$C:$C='LC Calculations'!D6)+('LC Raw Results'!$C:$C='LC Calculations'!E6)))} -> #VALUE! | F30: {=TRANSPOSE(_xlfn._xlws.FILTER('LC Raw Results'!$F:$F,('LC Raw Results'!$C:$C='LC Calculations'!F6)+('LC Raw Results'!$C:$C='LC Calculations'!G6)+('LC Raw Results'!$C:$C='LC Calculations'!H6)))} -> #VALUE! | I30: {=TRANSPOSE(_xlfn._xlws.FILTER('LC Raw Results'!$F:$F,('LC Raw Results'!$C:$C='LC Calculations'!I6)+('LC Raw Results'!$C:$C='LC Calculations'!J6)+('LC Raw Results'!$C:$C='LC Calculations'!K6)))} -> #VALUE! | L30: {=TRANSPOSE(_xlfn._xlws.FILTER('LC Raw Results'!$F:$F,('LC Raw Results'!$C:$C='LC Calculations'!L6)+('LC Raw Results'!$C:$C='LC Calculations'!M6)+('LC Raw Results'!$C:$C='LC Calculations'!N6)))} -> #VALUE! | P30: 13 | Q30: {=_xlfn.ANCHORARRAY(I22)} -> #VALUE! | T30: =IFERROR(AVERAGEIF(_xlfn.ANCHORARRAY(Q30),"<>0"),0) -> 0 | U30: =IFERROR((_xlfn.STDEV.P(Q30:S30)/SQRT(3)),0) -> 0 | W30: =AVERAGE(_xlfn.ANCHORARRAY(I34)) -> #VALUE! | AA30: =IF(T30=0,0,10^((T30-'LC Analysis'!$V$37)/'LC Analysis'!$V$38)) -> 0 | AD30: =IF($Y$17="Yes",W30,AA30) -> 0
B31: B | C31: {=TRANSPOSE(_xlfn._xlws.FILTER('LC Raw Results'!$F:$F,('LC Raw Results'!$C:$C='LC Calculations'!C7)+('LC Raw Results'!$C:$C='LC Calculations'!D7)+('LC Raw Results'!$C:$C='LC Calculations'!E7)))} -> #VALUE! | F31: {=TRANSPOSE(_xlfn._xlws.FILTER('LC Raw Results'!$F:$F,('LC Raw Results'!$C:$C='LC Calculations'!F7)+('LC Raw Results'!$C:$C='LC Calculations'!G7)+('LC Raw Results'!$C:$C='LC Calculations'!H7)))} -> #VALUE! | I31: {=TRANSPOSE(_xlfn._xlws.FILTER('LC Raw Results'!$F:$F,('LC Raw Results'!$C:$C='LC Calculations'!I7)+('LC Raw Results'!$C:$C='LC Calculations'!J7)+('LC Raw Results'!$C:$C='LC Calculations'!K7)))} -> #VALUE! | L31: {=TRANSPOSE(_xlfn._xlws.FILTER('LC Raw Results'!$F:$F,('LC Raw Results'!$C:$C='LC Calculations'!L7)+('LC Raw Results'!$C:$C='LC Calculations'!M7)+('LC Raw Results'!$C:$C='LC Calculations'!N7)))} -> #VALUE! | P31: 14 | Q31: {=_xlfn.ANCHORARRAY(I23)} -> #VALUE! | T31: =IFERROR(AVERAGEIF(_xlfn.ANCHORARRAY(Q31),"<>0"),0) -> 0 | U31: =IFERROR((_xlfn.STDEV.P(Q31:S31)/SQRT(3)),0) -> 0 | W31: =AVERAGE(_xlfn.ANCHORARRAY(I35)) -> #VALUE! | AA31: =IF(T31=0,0,10^((T31-'LC Analysis'!$V$37)/'LC Analysis'!$V$38)) -> 0 | AD31: =IF($Y$17="Yes",W31,AA31) -> 0
B32: C | C32: {=TRANSPOSE(_xlfn._xlws.FILTER('LC Raw Results'!$F:$F,('LC Raw Results'!$C:$C='LC Calculations'!C8)+('LC Raw Results'!$C:$C='LC Calculations'!D8)+('LC Raw Results'!$C:$C='LC Calculations'!E8)))} -> #VALUE! | F32: {=TRANSPOSE(_xlfn._xlws.FILTER('LC Raw Results'!$F:$F,('LC Raw Results'!$C:$C='LC Calculations'!F8)+('LC Raw Results'!$C:$C='LC Calculations'!G8)+('LC Raw Results'!$C:$C='LC Calculations'!H8)))} -> #VALUE! | I32: {=TRANSPOSE(_xlfn._xlws.FILTER('LC Raw Results'!$F:$F,('LC Raw Results'!$C:$C='LC Calculations'!I8)+('LC Raw Results'!$C:$C='LC Calculations'!J8)+('LC Raw Results'!$C:$C='LC Calculations'!K8)))} -> #VALUE! | L32: {=TRANSPOSE(_xlfn._xlws.FILTER('LC Raw Results'!$F:$F,('LC Raw Results'!$C:$C='LC Calculations'!L8)+('LC Raw Results'!$C:$C='LC Calculations'!M8)+('LC Raw Results'!$C:$C='LC Calculations'!N8)))} -> #VALUE! | P32: 15 | Q32: {=_xlfn.ANCHORARRAY(I24)} -> #VALUE! | T32: =IFERROR(AVERAGEIF(_xlfn.ANCHORARRAY(Q32),"<>0"),0) -> 0 | U32: =IFERROR((_xlfn.STDEV.P(Q32:S32)/SQRT(3)),0) -> 0 | W32: =AVERAGE(_xlfn.ANCHORARRAY(I36)) -> #VALUE! | AA32: =IF(T32=0,0,10^((T32-'LC Analysis'!$V$37)/'LC Analysis'!$V$38)) -> 0 | AD32: =IF($Y$17="Yes",W32,AA32) -> 0
B33: D | C33: {=TRANSPOSE(_xlfn._xlws.FILTER('LC Raw Results'!$F:$F,('LC Raw Results'!$C:$C='LC Calculations'!C9)+('LC Raw Results'!$C:$C='LC Calculations'!D9)+('LC Raw Results'!$C:$C='LC Calculations'!E9)))} -> #VALUE! | F33: {=TRANSPOSE(_xlfn._xlws.FILTER('LC Raw Results'!$F:$F,('LC Raw Results'!$C:$C='LC Calculations'!F9)+('LC Raw Results'!$C:$C='LC Calculations'!G9)+('LC Raw Results'!$C:$C='LC Calculations'!H9)))} -> #VALUE! | I33: {=TRANSPOSE(_xlfn._xlws.FILTER('LC Raw Results'!$F:$F,('LC Raw Results'!$C:$C='LC Calculations'!I9)+('LC Raw Results'!$C:$C='LC Calculations'!J9)+('LC Raw Results'!$C:$C='LC Calculations'!K9)))} -> #VALUE! | L33: {=TRANSPOSE(_xlfn._xlws.FILTER('LC Raw Results'!$F:$F,('LC Raw Results'!$C:$C='LC Calculations'!L9)+('LC Raw Results'!$C:$C='LC Calculations'!M9)+('LC Raw Results'!$C:$C='LC Calculations'!N9)))} -> #VALUE! | P33: 16 | Q33: {=_xlfn.ANCHORARRAY(I25)} -> #VALUE! | T33: =IFERROR(AVERAGEIF(_xlfn.ANCHORARRAY(Q33),"<>0"),0) -> 0 | U33: =IFERROR((_xlfn.STDEV.P(Q33:S33)/SQRT(3)),0) -> 0 | W33: =AVERAGE(_xlfn.ANCHORARRAY(I37)) -> #VALUE! | AA33: =IF(T33=0,0,10^((T33-'LC Analysis'!$V$37)/'LC Analysis'!$V$38)) -> 0 | AD33: =IF($Y$17="Yes",W33,AA33) -> 0
B34: E | C34: {=TRANSPOSE(_xlfn._xlws.FILTER('LC Raw Results'!$F:$F,('LC Raw Results'!$C:$C='LC Calculations'!C10)+('LC Raw Results'!$C:$C='LC Calculations'!D10)+('LC Raw Results'!$C:$C='LC Calculations'!E10)))} -> #VALUE! | F34: {=TRANSPOSE(_xlfn._xlws.FILTER('LC Raw Results'!$F:$F,('LC Raw Results'!$C:$C='LC Calculations'!F10)+('LC Raw Results'!$C:$C='LC Calculations'!G10)+('LC Raw Results'!$C:$C='LC Calculations'!H10)))} -> #VALUE! | I34: {=TRANSPOSE(_xlfn._xlws.FILTER('LC Raw Results'!$F:$F,('LC Raw Results'!$C:$C='LC Calculations'!I10)+('LC Raw Results'!$C:$C='LC Calculations'!J10)+('LC Raw Results'!$C:$C='LC Calculations'!K10)))} -> #VALUE! | L34: {=TRANSPOSE(_xlfn._xlws.FILTER('LC Raw Results'!$F:$F,('LC Raw Results'!$C:$C='LC Calculations'!L10)+('LC Raw Results'!$C:$C='LC Calculations'!M10)+('LC Raw Results'!$C:$C='LC Calculations'!N10)))} -> #VALUE! | P34: 17 | Q34: {=_xlfn.ANCHORARRAY(L18)} -> #VALUE! | T34: =IFERROR(AVERAGEIF(_xlfn.ANCHORARRAY(Q34),"<>0"),0) -> 0 | U34: =IFERROR((_xlfn.STDEV.P(Q34:S34)/SQRT(3)),0) -> 0 | W34: =AVERAGE(_xlfn.ANCHORARRAY(L30)) -> #VALUE! | AA34: =IF(T34=0,0,10^((T34-'LC Analysis'!$V$37)/'LC Analysis'!$V$38)) -> 0 | AD34: =IF($Y$17="Yes",W34,AA34) -> 0
B35: F | C35: {=TRANSPOSE(_xlfn._xlws.FILTER('LC Raw Results'!$F:$F,('LC Raw Results'!$C:$C='LC Calculations'!C11)+('LC Raw Results'!$C:$C='LC Calculations'!D11)+('LC Raw Results'!$C:$C='LC Calculations'!E11)))} -> #VALUE! | F35: {=TRANSPOSE(_xlfn._xlws.FILTER('LC Raw Results'!$F:$F,('LC Raw Results'!$C:$C='LC Calculations'!F11)+('LC Raw Results'!$C:$C='LC Calculations'!G11)+('LC Raw Results'!$C:$C='LC Calculations'!H11)))} -> #VALUE! | I35: {=TRANSPOSE(_xlfn._xlws.FILTER('LC Raw Results'!$F:$F,('LC Raw Results'!$C:$C='LC Calculations'!I11)+('LC Raw Results'!$C:$C='LC Calculations'!J11)+('LC Raw Results'!$C:$C='LC Calculations'!K11)))} -> #VALUE! | L35: {=TRANSPOSE(_xlfn._xlws.FILTER('LC Raw Results'!$F:$F,('LC Raw Results'!$C:$C='LC Calculations'!L11)+('LC Raw Results'!$C:$C='LC Calculations'!M11)+('LC Raw Results'!$C:$C='LC Calculations'!N11)))} -> #VALUE! | P35: 18 | Q35: {=_xlfn.ANCHORARRAY(L19)} -> #VALUE! | T35: =IFERROR(AVERAGEIF(_xlfn.ANCHORARRAY(Q35),"<>0"),0) -> 0 | U35: =IFERROR((_xlfn.STDEV.P(Q35:S35)/SQRT(3)),0) -> 0 | W35: =AVERAGE(_xlfn.ANCHORARRAY(L31)) -> #VALUE! | AA35: =IF(T35=0,0,10^((T35-'LC Analysis'!$V$37)/'LC Analysis'!$V$38)) -> 0 | AD35: =IF($Y$17="Yes",W35,AA35) -> 0
B36: G | C36: {=TRANSPOSE(_xlfn._xlws.FILTER('LC Raw Results'!$F:$F,('LC Raw Results'!$C:$C='LC Calculations'!C12)+('LC Raw Results'!$C:$C='LC Calculations'!D12)+('LC Raw Results'!$C:$C='LC Calculations'!E12)))} -> #VALUE! | F36: {=TRANSPOSE(_xlfn._xlws.FILTER('LC Raw Results'!$F:$F,('LC Raw Results'!$C:$C='LC Calculations'!F12)+('LC Raw Results'!$C:$C='LC Calculations'!G12)+('LC Raw Results'!$C:$C='LC Calculations'!H12)))} -> #VALUE! | I36: {=TRANSPOSE(_xlfn._xlws.FILTER('LC Raw Results'!$F:$F,('LC Raw Results'!$C:$C='LC Calculations'!I12)+('LC Raw Results'!$C:$C='LC Calculations'!J12)+('LC Raw Results'!$C:$C='LC Calculations'!K12)))} -> #VALUE! | L36: {=TRANSPOSE(_xlfn._xlws.FILTER('LC Raw Results'!$F:$F,('LC Raw Results'!$C:$C='LC Calculations'!L12)+('LC Raw Results'!$C:$C='LC Calculations'!M12)+('LC Raw Results'!$C:$C='LC Calculations'!N12)))} -> #VALUE! | P36: 19 | Q36: {=_xlfn.ANCHORARRAY(L20)} -> #VALUE! | T36: =IFERROR(AVERAGEIF(_xlfn.ANCHORARRAY(Q36),"<>0"),0) -> 0 | U36: =IFERROR((_xlfn.STDEV.P(Q36:S36)/SQRT(3)),0) -> 0 | W36: =AVERAGE(_xlfn.ANCHORARRAY(L32)) -> #VALUE! | AA36: =IF(T36=0,0,10^((T36-'LC Analysis'!$V$37)/'LC Analysis'!$V$38)) -> 0 | AD36: =IF($Y$17="Yes",W36,AA36) -> 0
B37: H | C37: {=TRANSPOSE(_xlfn._xlws.FILTER('LC Raw Results'!$F:$F,('LC Raw Results'!$C:$C='LC Calculations'!C13)+('LC Raw Results'!$C:$C='LC Calculations'!D13)+('LC Raw Results'!$C:$C='LC Calculations'!E13)))} -> #VALUE! | F37: {=TRANSPOSE(_xlfn._xlws.FILTER('LC Raw Results'!$F:$F,('LC Raw Results'!$C:$C='LC Calculations'!F13)+('LC Raw Results'!$C:$C='LC Calculations'!G13)+('LC Raw Results'!$C:$C='LC Calculations'!H13)))} -> #VALUE! | I37: {=TRANSPOSE(_xlfn._xlws.FILTER('LC Raw Results'!$F:$F,('LC Raw Results'!$C:$C='LC Calculations'!I13)+('LC Raw Results'!$C:$C='LC Calculations'!J13)+('LC Raw Results'!$C:$C='LC Calculations'!K13)))} -> #VALUE! | L37: {=TRANSPOSE(_xlfn._xlws.FILTER('LC Raw Results'!$F:$F,('LC Raw Results'!$C:$C='LC Calculations'!L13)+('LC Raw Results'!$C:$C='LC Calculations'!M13)+('LC Raw Results'!$C:$C='LC Calculations'!N13)))} -> #VALUE! | P37: 20 | Q37: {=_xlfn.ANCHORARRAY(L21)} -> #VALUE! | T37: =IFERROR(AVERAGEIF(_xlfn.ANCHORARRAY(Q37),"<>0"),0) -> 0 | U37: =IFERROR((_xlfn.STDEV.P(Q37:S37)/SQRT(3)),0) -> 0 | W37: =AVERAGE(_xlfn.ANCHORARRAY(L33)) -> #VALUE! | AA37: =IF(T37=0,0,10^((T37-'LC Analysis'!$V$37)/'LC Analysis'!$V$38)) -> 0 | AD37: =IF($Y$17="Yes",W37,AA37) -> 0
P38: 21 | Q38: {=_xlfn.ANCHORARRAY(L22)} -> #VALUE! | T38: =IFERROR(AVERAGEIF(_xlfn.ANCHORARRAY(Q38),"<>0"),0) -> 0 | U38: =IFERROR((_xlfn.STDEV.P(Q38:S38)/SQRT(3)),0) -> 0 | W38: =AVERAGE(_xlfn.ANCHORARRAY(L34)) -> #VALUE! | AA38: =IF(T38=0,0,10^((T38-'LC Analysis'!$V$37)/'LC Analysis'!$V$38)) -> 0 | AD38: =IF($Y$17="Yes",W38,AA38) -> 0
P39: 22 | Q39: {=_xlfn.ANCHORARRAY(L23)} -> #VALUE! | T39: =IFERROR(AVERAGEIF(_xlfn.ANCHORARRAY(Q39),"<>0"),0) -> 0 | U39: =IFERROR((_xlfn.STDEV.P(Q39:S39)/SQRT(3)),0) -> 0 | W39: =AVERAGE(_xlfn.ANCHORARRAY(L35)) -> #VALUE! | AA39: =IF(T39=0,0,10^((T39-'LC Analysis'!$V$37)/'LC Analysis'!$V$38)) -> 0 | AD39: =IF($Y$17="Yes",W39,AA39) -> 0
P40: 23 | Q40: {=_xlfn.ANCHORARRAY(L24)} -> #VALUE! | T40: =IFERROR(AVERAGEIF(_xlfn.ANCHORARRAY(Q40),"<>0"),0) -> 0 | U40: =IFERROR((_xlfn.STDEV.P(Q40:S40)/SQRT(3)),0) -> 0 | W40: =AVERAGE(_xlfn.ANCHORARRAY(L36)) -> #VALUE! | AA40: =IF(T40=0,0,10^((T40-'LC Analysis'!$V$37)/'LC Analysis'!$V$38)) -> 0 | AD40: =IF($Y$17="Yes",W40,AA40) -> 0
P41: 24 | Q41: {=_xlfn.ANCHORARRAY(L25)} -> #VALUE! | T41: =IFERROR(AVERAGEIF(_xlfn.ANCHORARRAY(Q41),"<>0"),0) -> 0 | U41: =IFERROR((_xlfn.STDEV.P(Q41:S41)/SQRT(3)),0) -> 0 | W41: =AVERAGE(_xlfn.ANCHORARRAY(L37)) -> #VALUE! | AA41: =IF(T41=0,0,10^((T41-'LC Analysis'!$V$37)/'LC Analysis'!$V$38)) -> 0 | AD41: =IF($Y$17="Yes",W41,AA41) -> 0

Sheet LC Analysis
A1: =IF('LC Raw Results'!A2>1,RIGHT('LC Raw Results'!A2,LEN('LC Raw Results'!A2)-12),"Paste Results File into Cell A2 of LC Raw Results") -> Paste Results File into Cell A2 of LC Raw Results
O2: Promega Conc. (ug/mL): | P2: 244
D3: PCR1 or PCR2?: | E3: PCR2 | K3: Standard Curve Analysis | O3: Promega Used (uL): | P3: 12.3 | T3: Pass/Fail?
B4: Tabulated Averages
D5: PCR1 Means | G5: PCR2 Means | K5: Actual Results | O5: Expected Results | T5: =IF(O63="TRUE","PASSED","FAILED") -> #DIV/0!
B6: Sample No. | C6: Sample ID | D6: Cp | E6: Conc. (ng/mL) | F6: Cp SEM | G6: 1/10 Cp | H6: Conc. (ng/mL)* | I6: Cp SEM | K6: Standard | L6: Mean Cp | M6: Mean Conc. (ng/mL)* | O6: Standard | P6: Mean Cp* | Q6: Mean Conc. (ng/mL)
B7: 1 | C7: =IF(ISBLANK('Sample List'!C6)=TRUE,"",'Sample List'!C6) -> PD005745RME2_D_Hu_01 | D7: {=IF($E$3="PCR1",_xlfn._xlws.FILTER('LC Calculations'!$T$18:$T$41,'LC Calculations'!$P$18:$P$41=B7),"")} | E7: {=IF($E$3="PCR1",_xlfn._xlws.FILTER('LC Calculations'!$AD$18:$AD$41,'LC Calculations'!$P$18:$P$41=B7),"")} | F7: {=IF($E$3="PCR1",_xlfn._xlws.FILTER('LC Calculations'!$U$18:$U$41,'LC Calculations'!$P$18:$P$41=B7),"")} | G7: {=IF($E$3="PCR2",_xlfn._xlws.FILTER('LC Calculations'!$T$18:$T$41,'LC Calculations'!$P$18:$P$41=B7),"")} -> 0 | H7: {=IF($E$3="PCR2",10*_xlfn._xlws.FILTER('LC Calculations'!$AD$18:$AD$41,'LC Calculations'!$P$18:$P$41=B7),"")} -> 0 | I7: {=IF($E$3="PCR2",_xlfn._xlws.FILTER('LC Calculations'!$U$18:$U$41,'LC Calculations'!$P$18:$P$41=B7),"")} -> 0 | K7: S1 | L7: ='LC Calculations'!T6 -> 0 | M7: ='LC Calculations'!AD6 -> 0 | O7: S1 | P7: =LOG(((3.6*(10^11))/((2*(Q7/1000))/0.00646246)),2) -> 22.886109 | Q7: =(P2*1000)*(P3/20) -> 150060
B8: 2 | C8: =IF(ISBLANK('Sample List'!C7)=TRUE,"",'Sample List'!C7) -> PD005599RME1_D_Hu_01 | D8: {=IF($E$3="PCR1",_xlfn._xlws.FILTER('LC Calculations'!$T$18:$T$41,'LC Calculations'!$P$18:$P$41=B8),"")} | E8: {=IF($E$3="PCR1",_xlfn._xlws.FILTER('LC Calculations'!$AD$18:$AD$41,'LC Calculations'!$P$18:$P$41=B8),"")} | F8: {=IF($E$3="PCR1",_xlfn._xlws.FILTER('LC Calculations'!$U$18:$U$41,'LC Calculations'!$P$18:$P$41=B8),"")} | G8: {=IF($E$3="PCR2",_xlfn._xlws.FILTER('LC Calculations'!$T$18:$T$41,'LC Calculations'!$P$18:$P$41=B8),"")} -> 0 | H8: {=IF($E$3="PCR2",10*_xlfn._xlws.FILTER('LC Calculations'!$AD$18:$AD$41,'LC Calculations'!$P$18:$P$41=B8),"")} -> 0 | I8: {=IF($E$3="PCR2",_xlfn._xlws.FILTER('LC Calculations'!$U$18:$U$41,'LC Calculations'!$P$18:$P$41=B8),"")} -> 0 | K8: S2 | L8: ='LC Calculations'!T7 -> 0 | M8: ='LC Calculations'!AD7 -> 0 | O8: S2 | P8: =LOG(((3.6*(10^11))/((2*(Q8/1000))/0.00646246)),2) -> 25.038113 | Q8: =Q7*(4.5/20) -> 33763.5
B9: 3 | C9: =IF(ISBLANK('Sample List'!C8)=TRUE,"",'Sample List'!C8) -> PD005595RME1_D_Hu_01 | D9: {=IF($E$3="PCR1",_xlfn._xlws.FILTER('LC Calculations'!$T$18:$T$41,'LC Calculations'!$P$18:$P$41=B9),"")} | E9: {=IF($E$3="PCR1",_xlfn._xlws.FILTER('LC Calculations'!$AD$18:$AD$41,'LC Calculations'!$P$18:$P$41=B9),"")} | F9: {=IF($E$3="PCR1",_xlfn._xlws.FILTER('LC Calculations'!$U$18:$U$41,'LC Calculations'!$P$18:$P$41=B9),"")} | G9: {=IF($E$3="PCR2",_xlfn._xlws.FILTER('LC Calculations'!$T$18:$T$41,'LC Calculations'!$P$18:$P$41=B9),"")} -> 0 | H9: {=IF($E$3="PCR2",10*_xlfn._xlws.FILTER('LC Calculations'!$AD$18:$AD$41,'LC Calculations'!$P$18:$P$41=B9),"")} -> 0 | I9: {=IF($E$3="PCR2",_xlfn._xlws.FILTER('LC Calculations'!$U$18:$U$41,'LC Calculations'!$P$18:$P$41=B9),"")} -> 0 | K9: S3 | L9: ='LC Calculations'!T8 -> 0 | M9: ='LC Calculations'!AD8 -> 0 | O9: S3 | P9: =LOG(((3.6*(10^11))/((2*(Q9/1000))/0.00646246)),2) -> 27.190116 | Q9: =Q8*(4.5/20) -> 7596.7875
B10: 4 | C10: =IF(ISBLANK('Sample List'!C9)=TRUE,"",'Sample List'!C9) -> PD005590RME1_D_Hu_01 | D10: {=IF($E$3="PCR1",_xlfn._xlws.FILTER('LC Calculations'!$T$18:$T$41,'LC Calculations'!$P$18:$P$41=B10),"")} | E10: {=IF($E$3="PCR1",_xlfn._xlws.FILTER('LC Calculations'!$AD$18:$AD$41,'LC Calculations'!$P$18:$P$41=B10),"")} | F10: {=IF($E$3="PCR1",_xlfn._xlws.FILTER('LC Calculations'!$U$18:$U$41,'LC Calculations'!$P$18:$P$41=B10),"")} | G10: {=IF($E$3="PCR2",_xlfn._xlws.FILTER('LC Calculations'!$T$18:$T$41,'LC Calculations'!$P$18:$P$41=B10),"")} -> 0 | H10: {=IF($E$3="PCR2",10*_xlfn._xlws.FILTER('LC Calculations'!$AD$18:$AD$41,'LC Calculations'!$P$18:$P$41=B10),"")} -> 0 | I10: {=IF($E$3="PCR2",_xlfn._xlws.FILTER('LC Calculations'!$U$18:$U$41,'LC Calculations'!$P$18:$P$41=B10),"")} -> 0 | K10: S4 | L10: ='LC Calculations'!T9 -> 0 | M10: ='LC Calculations'!AD9 -> 0 | O10: S4 | P10: =LOG(((3.6*(10^11))/((2*(Q10/1000))/0.00646246)),2) -> 29.342119 | Q10: =Q9*(4.5/20) -> 1709.2772
B11: 5 | C11: =IF(ISBLANK('Sample List'!C10)=TRUE,"",'Sample List'!C10) -> PD005585RME1_D_Hu_01 | D11: {=IF($E$3="PCR1",_xlfn._xlws.FILTER('LC Calculations'!$T$18:$T$41,'LC Calculations'!$P$18:$P$41=B11),"")} | E11: {=IF($E$3="PCR1",_xlfn._xlws.FILTER('LC Calculations'!$AD$18:$AD$41,'LC Calculations'!$P$18:$P$41=B11),"")} | F11: {=IF($E$3="PCR1",_xlfn._xlws.FILTER('LC Calculations'!$U$18:$U$41,'LC Calculations'!$P$18:$P$41=B11),"")} | G11: {=IF($E$3="PCR2",_xlfn._xlws.FILTER('LC Calculations'!$T$18:$T$41,'LC Calculations'!$P$18:$P$41=B11),"")} -> 0 | H11: {=IF($E$3="PCR2",10*_xlfn._xlws.FILTER('LC Calculations'!$AD$18:$AD$41,'LC Calculations'!$P$18:$P$41=B11),"")} -> 0 | I11: {=IF($E$3="PCR2",_xlfn._xlws.FILTER('LC Calculations'!$U$18:$U$41,'LC Calculations'!$P$18:$P$41=B11),"")} -> 0 | K11: S5 | L11: ='LC Calculations'!T10 -> 0 | M11: ='LC Calculations'!AD10 -> 0 | O11: S5 | P11: =LOG(((3.6*(10^11))/((2*(Q11/1000))/0.00646246)),2) -> 31.494122 | Q11: =Q10*(4.5/20) -> 384.58737
B12: 6 | C12: =IF(ISBLANK('Sample List'!C11)=TRUE,"",'Sample List'!C11) -> PD005594RME1_D_Hu_01 | D12: {=IF($E$3="PCR1",_xlfn._xlws.FILTER('LC Calculations'!$T$18:$T$41,'LC Calculations'!$P$18:$P$41=B12),"")} | E12: {=IF($E$3="PCR1",_xlfn._xlws.FILTER('LC Calculations'!$AD$18:$AD$41,'LC Calculations'!$P$18:$P$41=B12),"")} | F12: {=IF($E$3="PCR1",_xlfn._xlws.FILTER('LC Calculations'!$U$18:$U$41,'LC Calculations'!$P$18:$P$41=B12),"")} | G12: {=IF($E$3="PCR2",_xlfn._xlws.FILTER('LC Calculations'!$T$18:$T$41,'LC Calculations'!$P$18:$P$41=B12),"")} -> 0 | H12: {=IF($E$3="PCR2",10*_xlfn._xlws.FILTER('LC Calculations'!$AD$18:$AD$41,'LC Calculations'!$P$18:$P$41=B12),"")} -> 0 | I12: {=IF($E$3="PCR2",_xlfn._xlws.FILTER('LC Calculations'!$U$18:$U$41,'LC Calculations'!$P$18:$P$41=B12),"")} -> 0 | K12: S6 | L12: ='LC Calculations'!T11 -> 0 | M12: ='LC Calculations'!AD11 -> 0 | O12: S6 | P12: =LOG(((3.6*(10^11))/((2*(Q12/1000))/0.00646246)),2) -> 33.646125 | Q12: =Q11*(4.5/20) -> 86.532158
B13: 7 | C13: =IF(ISBLANK('Sample List'!C12)=TRUE,"",'Sample List'!C12) -> PD005593RME1_D_Hu_01 | D13: {=IF($E$3="PCR1",_xlfn._xlws.FILTER('LC Calculations'!$T$18:$T$41,'LC Calculations'!$P$18:$P$41=B13),"")} | E13: {=IF($E$3="PCR1",_xlfn._xlws.FILTER('LC Calculations'!$AD$18:$AD$41,'LC Calculations'!$P$18:$P$41=B13),"")} | F13: {=IF($E$3="PCR1",_xlfn._xlws.FILTER('LC Calculations'!$U$18:$U$41,'LC Calculations'!$P$18:$P$41=B13),"")} | G13: {=IF($E$3="PCR2",_xlfn._xlws.FILTER('LC Calculations'!$T$18:$T$41,'LC Calculations'!$P$18:$P$41=B13),"")} -> 0 | H13: {=IF($E$3="PCR2",10*_xlfn._xlws.FILTER('LC Calculations'!$AD$18:$AD$41,'LC Calculations'!$P$18:$P$41=B13),"")} -> 0 | I13: {=IF($E$3="PCR2",_xlfn._xlws.FILTER('LC Calculations'!$U$18:$U$41,'LC Calculations'!$P$18:$P$41=B13),"")} -> 0 | K13: POS | L13: ='LC Calculations'!T12 -> 0 | M13: ='LC Calculations'!AD12 -> 0 | O13: POS | P13: =LOG(((3.6*(10^11))/((2*(Q13/1000))/0.00646246)),2) -> 26.793577 | Q13: 10000
B14: 8 | C14: =IF(ISBLANK('Sample List'!C13)=TRUE,"",'Sample List'!C13) -> PD005592RME1_D_Hu_01 | D14: {=IF($E$3="PCR1",_xlfn._xlws.FILTER('LC Calculations'!$T$18:$T$41,'LC Calculations'!$P$18:$P$41=B14),"")} | E14: {=IF($E$3="PCR1",_xlfn._xlws.FILTER('LC Calculations'!$AD$18:$AD$41,'LC Calculations'!$P$18:$P$41=B14),"")} | F14: {=IF($E$3="PCR1",_xlfn._xlws.FILTER('LC Calculations'!$U$18:$U$41,'LC Calculations'!$P$18:$P$41=B14),"")} | G14: {=IF($E$3="PCR2",_xlfn._xlws.FILTER('LC Calculations'!$T$18:$T$41,'LC Calculations'!$P$18:$P$41=B14),"")} -> 0 | H14: {=IF($E$3="PCR2",10*_xlfn._xlws.FILTER('LC Calculations'!$AD$18:$AD$41,'LC Calculations'!$P$18:$P$41=B14),"")} -> 0 | I14: {=IF($E$3="PCR2",_xlfn._xlws.FILTER('LC Calculations'!$U$18:$U$41,'LC Calculations'!$P$18:$P$41=B14),"")} -> 0 | K14: NTC | L14: ='LC Calculations'!T13 -> 0 | M14: ='LC Calculations'!AD13 -> 0 | O14: NTC | P14: 0 | Q14: 0
B15: 9 | C15: =IF(ISBLANK('Sample List'!C14)=TRUE,"",'Sample List'!C14) -> PD005584RME1_D_Hu_01 | D15: {=IF($E$3="PCR1",_xlfn._xlws.FILTER('LC Calculations'!$T$18:$T$41,'LC Calculations'!$P$18:$P$41=B15),"")} | E15: {=IF($E$3="PCR1",_xlfn._xlws.FILTER('LC Calculations'!$AD$18:$AD$41,'LC Calculations'!$P$18:$P$41=B15),"")} | F15: {=IF($E$3="PCR1",_xlfn._xlws.FILTER('LC Calculations'!$U$18:$U$41,'LC Calculations'!$P$18:$P$41=B15),"")} | G15: {=IF($E$3="PCR2",_xlfn._xlws.FILTER('LC Calculations'!$T$18:$T$41,'LC Calculations'!$P$18:$P$41=B15),"")} -> 0 | H15: {=IF($E$3="PCR2",10*_xlfn._xlws.FILTER('LC Calculations'!$AD$18:$AD$41,'LC Calculations'!$P$18:$P$41=B15),"")} -> 0 | I15: {=IF($E$3="PCR2",_xlfn._xlws.FILTER('LC Calculations'!$U$18:$U$41,'LC Calculations'!$P$18:$P$41=B15),"")} -> 0 | K15: *Based on the Following: | O15: *Based on the Following:
B16: 10 | C16: =IF(ISBLANK('Sample List'!C15)=TRUE,"",'Sample List'!C15) -> PD005578RME1_D_Hu_01 | D16: {=IF($E$3="PCR1",_xlfn._xlws.FILTER('LC Calculations'!$T$18:$T$41,'LC Calculations'!$P$18:$P$41=B16),"")} | E16: {=IF($E$3="PCR1",_xlfn._xlws.FILTER('LC Calculations'!$AD$18:$AD$41,'LC Calculations'!$P$18:$P$41=B16),"")} | F16: {=IF($E$3="PCR1",_xlfn._xlws.FILTER('LC Calculations'!$U$18:$U$41,'LC Calculations'!$P$18:$P$41=B16),"")} | G16: {=IF($E$3="PCR2",_xlfn._xlws.FILTER('LC Calculations'!$T$18:$T$41,'LC Calculations'!$P$18:$P$41=B16),"")} -> 0 | H16: {=IF($E$3="PCR2",10*_xlfn._xlws.FILTER('LC Calculations'!$AD$18:$AD$41,'LC Calculations'!$P$18:$P$41=B16),"")} -> 0 | I16: {=IF($E$3="PCR2",_xlfn._xlws.FILTER('LC Calculations'!$U$18:$U$41,'LC Calculations'!$P$18:$P$41=B16),"")} -> 0 | K16: Cp = ('Slope'*'LogConc')+'Y-Intercept' | O16: -> Formula "Predicted Cp = LOG(((3.6*(10^11))/'InputGenomeCopies'),2)"
B17: 11 | C17: =IF(ISBLANK('Sample List'!C16)=TRUE,"",'Sample List'!C16) -> PD005575RME1_D_Hu_01 | D17: {=IF($E$3="PCR1",_xlfn._xlws.FILTER('LC Calculations'!$T$18:$T$41,'LC Calculations'!$P$18:$P$41=B17),"")} | E17: {=IF($E$3="PCR1",_xlfn._xlws.FILTER('LC Calculations'!$AD$18:$AD$41,'LC Calculations'!$P$18:$P$41=B17),"")} | F17: {=IF($E$3="PCR1",_xlfn._xlws.FILTER('LC Calculations'!$U$18:$U$41,'LC Calculations'!$P$18:$P$41=B17),"")} | G17: {=IF($E$3="PCR2",_xlfn._xlws.FILTER('LC Calculations'!$T$18:$T$41,'LC Calculations'!$P$18:$P$41=B17),"")} -> 0 | H17: {=IF($E$3="PCR2",10*_xlfn._xlws.FILTER('LC Calculations'!$AD$18:$AD$41,'LC Calculations'!$P$18:$P$41=B17),"")} -> 0 | I17: {=IF($E$3="PCR2",_xlfn._xlws.FILTER('LC Calculations'!$U$18:$U$41,'LC Calculations'!$P$18:$P$41=B17),"")} -> 0 | K17: Conc (ng/mL) = 10^(('Mean Cp'-'Y-Intercept')/'Slope') | O17: -> 'InputGenomeCopies' = [Sample in Reaction (uL)*Conc(ng/uL)]/[Genome Mass(ng)]
B18: 12 | C18: =IF(ISBLANK('Sample List'!C17)=TRUE,"",'Sample List'!C17) -> PD005572RME1_D_Hu_01 | D18: {=IF($E$3="PCR1",_xlfn._xlws.FILTER('LC Calculations'!$T$18:$T$41,'LC Calculations'!$P$18:$P$41=B18),"")} | E18: {=IF($E$3="PCR1",_xlfn._xlws.FILTER('LC Calculations'!$AD$18:$AD$41,'LC Calculations'!$P$18:$P$41=B18),"")} | F18: {=IF($E$3="PCR1",_xlfn._xlws.FILTER('LC Calculations'!$U$18:$U$41,'LC Calculations'!$P$18:$P$41=B18),"")} | G18: {=IF($E$3="PCR2",_xlfn._xlws.FILTER('LC Calculations'!$T$18:$T$41,'LC Calculations'!$P$18:$P$41=B18),"")} -> 0 | H18: {=IF($E$3="PCR2",10*_xlfn._xlws.FILTER('LC Calculations'!$AD$18:$AD$41,'LC Calculations'!$P$18:$P$41=B18),"")} -> 0 | I18: {=IF($E$3="PCR2",_xlfn._xlws.FILTER('LC Calculations'!$U$18:$U$41,'LC Calculations'!$P$18:$P$41=B18),"")} -> 0 | O18: -> 1 Genome = 0.00646246ng
B19: 13 | C19: =IF(ISBLANK('Sample List'!C18)=TRUE,"",'Sample List'!C18) -> PD005571RME1_D_Hu_01 | D19: {=IF($E$3="PCR1",_xlfn._xlws.FILTER('LC Calculations'!$T$18:$T$41,'LC Calculations'!$P$18:$P$41=B19),"")} | E19: {=IF($E$3="PCR1",_xlfn._xlws.FILTER('LC Calculations'!$AD$18:$AD$41,'LC Calculations'!$P$18:$P$41=B19),"")} | F19: {=IF($E$3="PCR1",_xlfn._xlws.FILTER('LC Calculations'!$U$18:$U$41,'LC Calculations'!$P$18:$P$41=B19),"")} | G19: {=IF($E$3="PCR2",_xlfn._xlws.FILTER('LC Calculations'!$T$18:$T$41,'LC Calculations'!$P$18:$P$41=B19),"")} -> 0 | H19: {=IF($E$3="PCR2",10*_xlfn._xlws.FILTER('LC Calculations'!$AD$18:$AD$41,'LC Calculations'!$P$18:$P$41=B19),"")} -> 0 | I19: {=IF($E$3="PCR2",_xlfn._xlws.FILTER('LC Calculations'!$U$18:$U$41,'LC Calculations'!$P$18:$P$41=B19),"")} -> 0
B20: 14 | C20: =IF(ISBLANK('Sample List'!C19)=TRUE,"",'Sample List'!C19) -> PD005568RME1_D_Hu_01 | D20: {=IF($E$3="PCR1",_xlfn._xlws.FILTER('LC Calculations'!$T$18:$T$41,'LC Calculations'!$P$18:$P$41=B20),"")} | E20: {=IF($E$3="PCR1",_xlfn._xlws.FILTER('LC Calculations'!$AD$18:$AD$41,'LC Calculations'!$P$18:$P$41=B20),"")} | F20: {=IF($E$3="PCR1",_xlfn._xlws.FILTER('LC Calculations'!$U$18:$U$41,'LC Calculations'!$P$18:$P$41=B20),"")} | G20: {=IF($E$3="PCR2",_xlfn._xlws.FILTER('LC Calculations'!$T$18:$T$41,'LC Calculations'!$P$18:$P$41=B20),"")} -> 0 | H20: {=IF($E$3="PCR2",10*_xlfn._xlws.FILTER('LC Calculations'!$AD$18:$AD$41,'LC Calculations'!$P$18:$P$41=B20),"")} -> 0 | I20: {=IF($E$3="PCR2",_xlfn._xlws.FILTER('LC Calculations'!$U$18:$U$41,'LC Calculations'!$P$18:$P$41=B20),"")} -> 0 | K20: Standard Curve Breakdown
B21: 15 | C21: =IF(ISBLANK('Sample List'!C20)=TRUE,"",'Sample List'!C20) -> PD005565RME1_D_Hu_01 | D21: {=IF($E$3="PCR1",_xlfn._xlws.FILTER('LC Calculations'!$T$18:$T$41,'LC Calculations'!$P$18:$P$41=B21),"")} | E21: {=IF($E$3="PCR1",_xlfn._xlws.FILTER('LC Calculations'!$AD$18:$AD$41,'LC Calculations'!$P$18:$P$41=B21),"")} | F21: {=IF($E$3="PCR1",_xlfn._xlws.FILTER('LC Calculations'!$U$18:$U$41,'LC Calculations'!$P$18:$P$41=B21),"")} | G21: {=IF($E$3="PCR2",_xlfn._xlws.FILTER('LC Calculations'!$T$18:$T$41,'LC Calculations'!$P$18:$P$41=B21),"")} -> 0 | H21: {=IF($E$3="PCR2",10*_xlfn._xlws.FILTER('LC Calculations'!$AD$18:$AD$41,'LC Calculations'!$P$18:$P$41=B21),"")} -> 0 | I21: {=IF($E$3="PCR2",_xlfn._xlws.FILTER('LC Calculations'!$U$18:$U$41,'LC Calculations'!$P$18:$P$41=B21),"")} -> 0 | K21: Actual Results | Q21: Full Actual Results
B22: 16 | C22: =IF(ISBLANK('Sample List'!C21)=TRUE,"",'Sample List'!C21) -> PD005564RME4_D_Hu_01 | D22: {=IF($E$3="PCR1",_xlfn._xlws.FILTER('LC Calculations'!$T$18:$T$41,'LC Calculations'!$P$18:$P$41=B22),"")} | E22: {=IF($E$3="PCR1",_xlfn._xlws.FILTER('LC Calculations'!$AD$18:$AD$41,'LC Calculations'!$P$18:$P$41=B22),"")} | F22: {=IF($E$3="PCR1",_xlfn._xlws.FILTER('LC Calculations'!$U$18:$U$41,'LC Calculations'!$P$18:$P$41=B22),"")} | G22: {=IF($E$3="PCR2",_xlfn._xlws.FILTER('LC Calculations'!$T$18:$T$41,'LC Calculations'!$P$18:$P$41=B22),"")} -> 0 | H22: {=IF($E$3="PCR2",10*_xlfn._xlws.FILTER('LC Calculations'!$AD$18:$AD$41,'LC Calculations'!$P$18:$P$41=B22),"")} -> 0 | I22: {=IF($E$3="PCR2",_xlfn._xlws.FILTER('LC Calculations'!$U$18:$U$41,'LC Calculations'!$P$18:$P$41=B22),"")} -> 0 | K22: Standard | L22: Mean Cp | M22: Mean Conc. (ng/mL) | N22: Log Conc.* | Q22: Standard | R22: Cp 1 | S22: Cp 2 | T22: Cp 3 | U22: SEM | V22: ΔCt
B23: 17 | C23: =IF(ISBLANK('Sample List'!C22)=TRUE,"",'Sample List'!C22) -> PD005563RME1_D_Hu_01 | D23: {=IF($E$3="PCR1",_xlfn._xlws.FILTER('LC Calculations'!$T$18:$T$41,'LC Calculations'!$P$18:$P$41=B23),"")} | E23: {=IF($E$3="PCR1",_xlfn._xlws.FILTER('LC Calculations'!$AD$18:$AD$41,'LC Calculations'!$P$18:$P$41=B23),"")} | F23: {=IF($E$3="PCR1",_xlfn._xlws.FILTER('LC Calculations'!$U$18:$U$41,'LC Calculations'!$P$18:$P$41=B23),"")} | G23: {=IF($E$3="PCR2",_xlfn._xlws.FILTER('LC Calculations'!$T$18:$T$41,'LC Calculations'!$P$18:$P$41=B23),"")} -> 0 | H23: {=IF($E$3="PCR2",10*_xlfn._xlws.FILTER('LC Calculations'!$AD$18:$AD$41,'LC Calculations'!$P$18:$P$41=B23),"")} -> 0 | I23: {=IF($E$3="PCR2",_xlfn._xlws.FILTER('LC Calculations'!$U$18:$U$41,'LC Calculations'!$P$18:$P$41=B23),"")} -> 0 | K23: S1 | L23: =L7 -> 0 | M23: =M7 -> 0 | N23: =LOG(Q7) -> 5.1762649 | Q23: S1 | R23: ='LC Calculations'!Q6 -> #VALUE! | S23: ='LC Calculations'!R6 -> 0 | T23: ='LC Calculations'!S6 -> 0 | U23: ='LC Calculations'!U6 -> 0 | V23: -
B24: 18 | C24: =IF(ISBLANK('Sample List'!C23)=TRUE,"",'Sample List'!C23) -> PD005562RME1_D_Hu_01 | D24: {=IF($E$3="PCR1",_xlfn._xlws.FILTER('LC Calculations'!$T$18:$T$41,'LC Calculations'!$P$18:$P$41=B24),"")} | E24: {=IF($E$3="PCR1",_xlfn._xlws.FILTER('LC Calculations'!$AD$18:$AD$41,'LC Calculations'!$P$18:$P$41=B24),"")} | F24: {=IF($E$3="PCR1",_xlfn._xlws.FILTER('LC Calculations'!$U$18:$U$41,'LC Calculations'!$P$18:$P$41=B24),"")} | G24: {=IF($E$3="PCR2",_xlfn._xlws.FILTER('LC Calculations'!$T$18:$T$41,'LC Calculations'!$P$18:$P$41=B24),"")} -> 0 | H24: {=IF($E$3="PCR2",10*_xlfn._xlws.FILTER('LC Calculations'!$AD$18:$AD$41,'LC Calculations'!$P$18:$P$41=B24),"")} -> 0 | I24: {=IF($E$3="PCR2",_xlfn._xlws.FILTER('LC Calculations'!$U$18:$U$41,'LC Calculations'!$P$18:$P$41=B24),"")} -> 0 | K24: S2 | L24: =L8 -> 0 | M24: =M8 -> 0 | N24: =LOG(Q8) -> 4.5284475 | Q24: S2 | R24: ='LC Calculations'!Q7 -> #VALUE! | S24: ='LC Calculations'!R7 -> 0 | T24: ='LC Calculations'!S7 -> 0 | U24: ='LC Calculations'!U7 -> 0 | V24: =L24-L23 -> 0
B25: 19 | C25: =IF(ISBLANK('Sample List'!C24)=TRUE,"",'Sample List'!C24) -> PD005561RME1_D_Hu_01 | D25: {=IF($E$3="PCR1",_xlfn._xlws.FILTER('LC Calculations'!$T$18:$T$41,'LC Calculations'!$P$18:$P$41=B25),"")} | E25: {=IF($E$3="PCR1",_xlfn._xlws.FILTER('LC Calculations'!$AD$18:$AD$41,'LC Calculations'!$P$18:$P$41=B25),"")} | F25: {=IF($E$3="PCR1",_xlfn._xlws.FILTER('LC Calculations'!$U$18:$U$41,'LC Calculations'!$P$18:$P$41=B25),"")} | G25: {=IF($E$3="PCR2",_xlfn._xlws.FILTER('LC Calculations'!$T$18:$T$41,'LC Calculations'!$P$18:$P$41=B25),"")} -> 0 | H25: {=IF($E$3="PCR2",10*_xlfn._xlws.FILTER('LC Calculations'!$AD$18:$AD$41,'LC Calculations'!$P$18:$P$41=B25),"")} -> 0 | I25: {=IF($E$3="PCR2",_xlfn._xlws.FILTER('LC Calculations'!$U$18:$U$41,'LC Calculations'!$P$18:$P$41=B25),"")} -> 0 | K25: S3 | L25: =L9 -> 0 | M25: =M9 -> 0 | N25: =LOG(Q9) -> 3.88063 | Q25: S3 | R25: ='LC Calculations'!Q8 -> #VALUE! | S25: ='LC Calculations'!R8 -> 0 | T25: ='LC Calculations'!S8 -> 0 | U25: ='LC Calculations'!U8 -> 0 | V25: =L25-L24 -> 0
B26: 20 | C26: =IF(ISBLANK('Sample List'!C25)=TRUE,"",'Sample List'!C25) -> PD005558RME1_D_Hu_01 | D26: {=IF($E$3="PCR1",_xlfn._xlws.FILTER('LC Calculations'!$T$18:$T$41,'LC Calculations'!$P$18:$P$41=B26),"")} | E26: {=IF($E$3="PCR1",_xlfn._xlws.FILTER('LC Calculations'!$AD$18:$AD$41,'LC Calculations'!$P$18:$P$41=B26),"")} | F26: {=IF($E$3="PCR1",_xlfn._xlws.FILTER('LC Calculations'!$U$18:$U$41,'LC Calculations'!$P$18:$P$41=B26),"")} | G26: {=IF($E$3="PCR2",_xlfn._xlws.FILTER('LC Calculations'!$T$18:$T$41,'LC Calculations'!$P$18:$P$41=B26),"")} -> 0 | H26: {=IF($E$3="PCR2",10*_xlfn._xlws.FILTER('LC Calculations'!$AD$18:$AD$41,'LC Calculations'!$P$18:$P$41=B26),"")} -> 0 | I26: {=IF($E$3="PCR2",_xlfn._xlws.FILTER('LC Calculations'!$U$18:$U$41,'LC Calculations'!$P$18:$P$41=B26),"")} -> 0 | K26: S4 | L26: =L10 -> 0 | M26: =M10 -> 0 | N26: =LOG(Q10) -> 3.2328125 | Q26: S4 | R26: ='LC Calculations'!Q9 -> #VALUE! | S26: ='LC Calculations'!R9 -> 0 | T26: ='LC Calculations'!S9 -> 0 | U26: ='LC Calculations'!U9 -> 0 | V26: =L26-L25 -> 0
B27: 21 | C27: =IF(ISBLANK('Sample List'!C26)=TRUE,"",'Sample List'!C26) -> PD005557RME1_D_Hu_01 | D27: {=IF($E$3="PCR1",_xlfn._xlws.FILTER('LC Calculations'!$T$18:$T$41,'LC Calculations'!$P$18:$P$41=B27),"")} | E27: {=IF($E$3="PCR1",_xlfn._xlws.FILTER('LC Calculations'!$AD$18:$AD$41,'LC Calculations'!$P$18:$P$41=B27),"")} | F27: {=IF($E$3="PCR1",_xlfn._xlws.FILTER('LC Calculations'!$U$18:$U$41,'LC Calculations'!$P$18:$P$41=B27),"")} | G27: {=IF($E$3="PCR2",_xlfn._xlws.FILTER('LC Calculations'!$T$18:$T$41,'LC Calculations'!$P$18:$P$41=B27),"")} -> 0 | H27: {=IF($E$3="PCR2",10*_xlfn._xlws.FILTER('LC Calculations'!$AD$18:$AD$41,'LC Calculations'!$P$18:$P$41=B27),"")} -> 0 | I27: {=IF($E$3="PCR2",_xlfn._xlws.FILTER('LC Calculations'!$U$18:$U$41,'LC Calculations'!$P$18:$P$41=B27),"")} -> 0 | K27: S5 | L27: =L11 -> 0 | M27: =M11 -> 0 | N27: =LOG(Q11) -> 2.584995 | Q27: S5 | R27: ='LC Calculations'!Q10 -> #VALUE! | S27: ='LC Calculations'!R10 -> 0 | T27: ='LC Calculations'!S10 -> 0 | U27: ='LC Calculations'!U10 -> 0 | V27: =L27-L26 -> 0
B28: 22 | C28: =IF(ISBLANK('Sample List'!C27)=TRUE,"",'Sample List'!C27) -> PD005556RME1_D_Hu_01 | D28: {=IF($E$3="PCR1",_xlfn._xlws.FILTER('LC Calculations'!$T$18:$T$41,'LC Calculations'!$P$18:$P$41=B28),"")} | E28: {=IF($E$3="PCR1",_xlfn._xlws.FILTER('LC Calculations'!$AD$18:$AD$41,'LC Calculations'!$P$18:$P$41=B28),"")} | F28: {=IF($E$3="PCR1",_xlfn._xlws.FILTER('LC Calculations'!$U$18:$U$41,'LC Calculations'!$P$18:$P$41=B28),"")} | G28: {=IF($E$3="PCR2",_xlfn._xlws.FILTER('LC Calculations'!$T$18:$T$41,'LC Calculations'!$P$18:$P$41=B28),"")} -> 0 | H28: {=IF($E$3="PCR2",10*_xlfn._xlws.FILTER('LC Calculations'!$AD$18:$AD$41,'LC Calculations'!$P$18:$P$41=B28),"")} -> 0 | I28: {=IF($E$3="PCR2",_xlfn._xlws.FILTER('LC Calculations'!$U$18:$U$41,'LC Calculations'!$P$18:$P$41=B28),"")} -> 0 | K28: S6 | L28: =L12 -> 0 | M28: =M12 -> 0 | N28: =LOG(Q12) -> 1.9371775 | Q28: S6 | R28: ='LC Calculations'!Q11 -> #VALUE! | S28: ='LC Calculations'!R11 -> 0 | T28: ='LC Calculations'!S11 -> 0 | U28: ='LC Calculations'!U11 -> 0 | V28: =L28-L27 -> 0
B29: 23 | C29: =IF(ISBLANK('Sample List'!C28)=TRUE,"",'Sample List'!C28) -> DEN078-POS_D_Hu_01 | D29: {=IF($E$3="PCR1",_xlfn._xlws.FILTER('LC Calculations'!$T$18:$T$41,'LC Calculations'!$P$18:$P$41=B29),"")} | E29: {=IF($E$3="PCR1",_xlfn._xlws.FILTER('LC Calculations'!$AD$18:$AD$41,'LC Calculations'!$P$18:$P$41=B29),"")} | F29: {=IF($E$3="PCR1",_xlfn._xlws.FILTER('LC Calculations'!$U$18:$U$41,'LC Calculations'!$P$18:$P$41=B29),"")} | G29: {=IF($E$3="PCR2",_xlfn._xlws.FILTER('LC Calculations'!$T$18:$T$41,'LC Calculations'!$P$18:$P$41=B29),"")} -> 0 | H29: {=IF($E$3="PCR2",10*_xlfn._xlws.FILTER('LC Calculations'!$AD$18:$AD$41,'LC Calculations'!$P$18:$P$41=B29),"")} -> 0 | I29: {=IF($E$3="PCR2",_xlfn._xlws.FILTER('LC Calculations'!$U$18:$U$41,'LC Calculations'!$P$18:$P$41=B29),"")} -> 0 | K29: *Based on Expected Concentration
B30: 24 | C30: =IF(ISBLANK('Sample List'!C29)=TRUE,"",'Sample List'!C29) -> DEN078-NEG_D_Hu_01 | D30: {=IF($E$3="PCR1",_xlfn._xlws.FILTER('LC Calculations'!$T$18:$T$41,'LC Calculations'!$P$18:$P$41=B30),"")} | E30: {=IF($E$3="PCR1",_xlfn._xlws.FILTER('LC Calculations'!$AD$18:$AD$41,'LC Calculations'!$P$18:$P$41=B30),"")} | F30: {=IF($E$3="PCR1",_xlfn._xlws.FILTER('LC Calculations'!$U$18:$U$41,'LC Calculations'!$P$18:$P$41=B30),"")} | G30: {=IF($E$3="PCR2",_xlfn._xlws.FILTER('LC Calculations'!$T$18:$T$41,'LC Calculations'!$P$18:$P$41=B30),"")} -> 0 | H30: {=IF($E$3="PCR2",10*_xlfn._xlws.FILTER('LC Calculations'!$AD$18:$AD$41,'LC Calculations'!$P$18:$P$41=B30),"")} -> 0 | I30: {=IF($E$3="PCR2",_xlfn._xlws.FILTER('LC Calculations'!$U$18:$U$41,'LC Calculations'!$P$18:$P$41=B30),"")} -> 0
B31: ='Sample List'!B30 -> POS Control | C31: ='Sample List'!C30 -> Human Male DNA 10ng/uL | D31: =IF(E3="PCR1",'LC Calculations'!T12,"") | E31: =IF(E3="PCR1",'LC Calculations'!AD12,"") | F31: =IF(E3="PCR1",'LC Calculations'!U12,"") | G31: =IF(E3="PCR2",'LC Calculations'!T12,"") -> 0 | H31: =IF(E3="PCR2",'LC Calculations'!AD12,"") -> 0 | I31: =IF(E3="PCR2",'LC Calculations'!U12,"") -> 0 | K31: Graphical Representation
